<?xml version="1.0" ?>
<sdf version="1.9">
  <model name="uni_agv">
    <self_collide>false</self_collide>
    <link name="chassis">
      <pose>0 0 0.175 0 0 0</pose>
      <inertial>
        <mass>30.0</mass>
        <inertia>
          <ixx>0.781250</ixx>
          <ixy>0</ixy>
          <ixz>0</ixz>
          <iyy>1.056250</iyy>
          <iyz>0</iyz>
          <izz>1.525000</izz>
        </inertia>
      </inertial>
      <visual name="chassis_visual">
        <geometry>
          <box>
            <size>0.6 0.5 0.25</size>
          </box>
        </geometry>
        <material>
          <ambient>0.2 0.2 0.8 1.0</ambient>
          <diffuse>0.2 0.2 0.8 1.0</diffuse>
        </material>
      </visual>
      <collision name="chassis_collision">
        <geometry>
          <box>
            <size>0.6 0.5 0.25</size>
          </box>
        </geometry>
      </collision>
    </link>
    <link name="front_left_wheel">
      <pose>0.25 0.2 0.05 1.5707963267948966 0 0</pose>
      <inertial>
        <mass>1.0</mass>
        <inertia>
          <ixx>0.000758</ixx>
          <ixy>0</ixy>
          <ixz>0</ixz>
          <iyy>0.000758</iyy>
          <iyz>0</iyz>
          <izz>0.001250</izz>
        </inertia>
      </inertial>
      <visual name="front_left_wheel_visual">
        <geometry>
          <cylinder>
            <radius>0.05</radius>
            <length>0.04</length>
          </cylinder>
        </geometry>
        <material>
          <ambient>0.1 0.1 0.1 1.0</ambient>
          <diffuse>0.1 0.1 0.1 1.0</diffuse>
        </material>
      </visual>
      <collision name="front_left_wheel_collision">
        <geometry>
          <cylinder>
            <radius>0.05</radius>
            <length>0.04</length>
          </cylinder>
        </geometry>
        <surface>
          <friction>
            <ode>
              <mu>1.0</mu>
              <mu2>1.0</mu2>
            </ode>
          </friction>
        </surface>
      </collision>
    </link>
    <joint name="front_left_wheel_joint" type="revolute">
      <parent>chassis</parent>
      <child>front_left_wheel</child>
      <axis>
        <xyz>0 0 1</xyz>
        <limit>
          <lower>-1e16</lower>
          <upper>1e16</upper>
        </limit>
      </axis>
    </joint>
    <link name="front_right_wheel">
      <pose>0.25 -0.2 0.05 1.5707963267948966 0 0</pose>
      <inertial>
        <mass>1.0</mass>
        <inertia>
          <ixx>0.000758</ixx>
          <ixy>0</ixy>
          <ixz>0</ixz>
          <iyy>0.000758</iyy>
          <iyz>0</iyz>
          <izz>0.001250</izz>
        </inertia>
      </inertial>
      <visual name="front_right_wheel_visual">
        <geometry>
          <cylinder>
            <radius>0.05</radius>
            <length>0.04</length>
          </cylinder>
        </geometry>
        <material>
          <ambient>0.1 0.1 0.1 1.0</ambient>
          <diffuse>0.1 0.1 0.1 1.0</diffuse>
        </material>
      </visual>
      <collision name="front_right_wheel_collision">
        <geometry>
          <cylinder>
            <radius>0.05</radius>
            <length>0.04</length>
          </cylinder>
        </geometry>
        <surface>
          <friction>
            <ode>
              <mu>1.0</mu>
              <mu2>1.0</mu2>
            </ode>
          </friction>
        </surface>
      </collision>
    </link>
    <joint name="front_right_wheel_joint" type="revolute">
      <parent>chassis</parent>
      <child>front_right_wheel</child>
      <axis>
        <xyz>0 0 1</xyz>
        <limit>
          <lower>-1e16</lower>
          <upper>1e16</upper>
        </limit>
      </axis>
    </joint>
    <link name="rear_left_wheel">
      <pose>-0.25 0.2 0.05 1.5707963267948966 0 0</pose>
      <inertial>
        <mass>1.0</mass>
        <inertia>
          <ixx>0.000758</ixx>
          <ixy>0</ixy>
          <ixz>0</ixz>
          <iyy>0.000758</iyy>
          <iyz>0</iyz>
          <izz>0.001250</izz>
        </inertia>
      </inertial>
      <visual name="rear_left_wheel_visual">
        <geometry>
          <cylinder>
            <radius>0.05</radius>
            <length>0.04</length>
          </cylinder>
        </geometry>
        <material>
          <ambient>0.1 0.1 0.1 1.0</ambient>
          <diffuse>0.1 0.1 0.1 1.0</diffuse>
        </material>
      </visual>
      <collision name="rear_left_wheel_collision">
        <geometry>
          <cylinder>
            <radius>0.05</radius>
            <length>0.04</length>
          </cylinder>
        </geometry>
        <surface>
          <friction>
            <ode>
              <mu>1.0</mu>
              <mu2>1.0</mu2>
            </ode>
          </friction>
        </surface>
      </collision>
    </link>
    <joint name="rear_left_wheel_joint" type="revolute">
      <parent>chassis</parent>
      <child>rear_left_wheel</child>
      <axis>
        <xyz>0 0 1</xyz>
        <limit>
          <lower>-1e16</lower>
          <upper>1e16</upper>
        </limit>
      </axis>
    </joint>
    <link name="rear_right_wheel">
      <pose>-0.25 -0.2 0.05 1.5707963267948966 0 0</pose>
      <inertial>
        <mass>1.0</mass>
        <inertia>
          <ixx>0.000758</ixx>
          <ixy>0</ixy>
          <ixz>0</ixz>
          <iyy>0.000758</iyy>
          <iyz>0</iyz>
          <izz>0.001250</izz>
        </inertia>
      </inertial>
      <visual name="rear_right_wheel_visual">
        <geometry>
          <cylinder>
            <radius>0.05</radius>
            <length>0.04</length>
          </cylinder>
        </geometry>
        <material>
          <ambient>0.1 0.1 0.1 1.0</ambient>
          <diffuse>0.1 0.1 0.1 1.0</diffuse>
        </material>
      </visual>
      <collision name="rear_right_wheel_collision">
        <geometry>
          <cylinder>
            <radius>0.05</radius>
            <length>0.04</length>
          </cylinder>
        </geometry>
        <surface>
          <friction>
            <ode>
              <mu>1.0</mu>
              <mu2>1.0</mu2>
            </ode>
          </friction>
        </surface>
      </collision>
    </link>
    <joint name="rear_right_wheel_joint" type="revolute">
      <parent>chassis</parent>
      <child>rear_right_wheel</child>
      <axis>
        <xyz>0 0 1</xyz>
        <limit>
          <lower>-1e16</lower>
          <upper>1e16</upper>
        </limit>
      </axis>
    </joint>
    <plugin filename="gz-sim-diff-drive-system" name="gz::sim::systems::DiffDrive">
      <left_joint>front_left_wheel_joint</left_joint>
      <right_joint>front_right_wheel_joint</right_joint>
      <wheel_separation>0.4</wheel_separation>
      <wheel_radius>0.05</wheel_radius>
      <max_linear_acceleration>0.8</max_linear_acceleration>
      <max_angular_velocity>1.57</max_angular_velocity>
      <topic>cmd_vel</topic>
      <odom_topic>odom</odom_topic>
      <tf_topic>tf</tf_topic>
      <frame_id>odom</frame_id>
      <child_frame_id>chassis</child_frame_id>
      <odom_publish_frequency>15</odom_publish_frequency>
    </plugin>
    <link name="lidar_link">
      <pose>0 0 0.32 0 0 0</pose>
      <inertial>
        <mass>0.1</mass>
        <inertia>
          <ixx>0.000047</ixx>
          <ixy>0</ixy>
          <ixz>0</ixz>
          <iyy>0.000047</iyy>
          <iyz>0</iyz>
          <izz>0.000080</izz>
        </inertia>
      </inertial>
      <visual name="lidar_puck_visual">
        <geometry>
          <cylinder>
            <radius>0.04</radius>
            <length>0.03</length>
          </cylinder>
        </geometry>
        <material>
          <ambient>0.1 0.1 0.1 1.0</ambient>
          <diffuse>0.1 0.1 0.1 1.0</diffuse>
        </material>
      </visual>
      <collision name="lidar_puck_collision">
        <geometry>
          <cylinder>
            <radius>0.04</radius>
            <length>0.03</length>
          </cylinder>
        </geometry>
      </collision>
      <sensor name="lidar_sensor" type="gpu_lidar">
        <always_on>true</always_on>
        <update_rate>10</update_rate>
        <visualize>true</visualize>
        <topic>lidar</topic>
        <ray>
          <scan>
            <horizontal>
              <samples>30</samples>
              <resolution>1</resolution>
              <min_angle>-0.261799</min_angle>
              <max_angle>0.261799</max_angle>
            </horizontal>
          </scan>
          <range>
            <min>0.08</min>
            <max>1.5</max>
            <resolution>0.01</resolution>
          </range>
          <noise>
            <type>gaussian</type>
            <mean>0.0</mean>
            <stddev>0.03</stddev>
          </noise>
        </ray>
      </sensor>
    </link>
    <joint name="lidar_joint" type="fixed">
      <parent>chassis</parent>
      <child>lidar_link</child>
    </joint>
    <plugin filename="gz-sim-joint-state-publisher-system" name="gz::sim::systems::JointStatePublisher"/>
  </model>
</sdf>
