<?xml version="1.0" ?>
<sdf version="1.9">
  <model name="Addverb_Quadron">
    <self_collide>false</self_collide>

    <!-- ══ Chassis ══ -->
    <link name="chassis">
      <pose>0 0 0.115000 0 0 0</pose>
      <inertial>
        <mass>80.0</mass>
        <inertia>
          <ixx>5.550000</ixx><ixy>0</ixy><ixz>0</ixz>
          <iyy>9.750000</iyy><iyz>0</iyz>
          <izz>15.000000</izz>
        </inertia>
      </inertial>
      <visual name="chassis_visual">
        <geometry><box><size>1.2 0.9 0.15</size></box></geometry>
        <material>
          <ambient>0.9 0.35 0.1 1.0</ambient>
          <diffuse>0.9 0.35 0.1 1.0</diffuse>
        </material>
      </visual>
      <collision name="chassis_collision">
        <geometry><box><size>1.2 0.9 0.15</size></box></geometry>
      </collision>
    </link>

    <!-- ══ Left Wheel ══ -->
    <link name="left_wheel">
      <pose>0 0.350000 0.040000 1.5707963268 0 0</pose>
      <inertial>
        <mass>1.0</mass>
        <inertia>
          <ixx>0.000533</ixx><ixy>0</ixy><ixz>0</ixz>
          <iyy>0.000533</iyy><iyz>0</iyz>
          <izz>0.000800</izz>
        </inertia>
      </inertial>
      <visual name="left_wheel_visual">
        <geometry><cylinder><radius>0.04</radius><length>0.04</length></cylinder></geometry>
        <material><ambient>0.2 0.2 0.2 1.0</ambient><diffuse>0.2 0.2 0.2 1.0</diffuse></material>
      </visual>
      <collision name="left_wheel_collision">
        <geometry><cylinder><radius>0.04</radius><length>0.04</length></cylinder></geometry>
        <surface><friction><ode><mu>1.0</mu><mu2>1.0</mu2></ode></friction></surface>
      </collision>
    </link>
    <joint name="left_wheel_joint" type="revolute">
      <parent>chassis</parent><child>left_wheel</child>
      <axis><xyz>0 0 1</xyz><limit><lower>-1e16</lower><upper>1e16</upper></limit></axis>
    </joint>

    <!-- ══ Right Wheel ══ -->
    <link name="right_wheel">
      <pose>0 -0.350000 0.040000 1.5707963268 0 0</pose>
      <inertial>
        <mass>1.0</mass>
        <inertia>
          <ixx>0.000533</ixx><ixy>0</ixy><ixz>0</ixz>
          <iyy>0.000533</iyy><iyz>0</iyz>
          <izz>0.000800</izz>
        </inertia>
      </inertial>
      <visual name="right_wheel_visual">
        <geometry><cylinder><radius>0.04</radius><length>0.04</length></cylinder></geometry>
        <material><ambient>0.2 0.2 0.2 1.0</ambient><diffuse>0.2 0.2 0.2 1.0</diffuse></material>
      </visual>
      <collision name="right_wheel_collision">
        <geometry><cylinder><radius>0.04</radius><length>0.04</length></cylinder></geometry>
        <surface><friction><ode><mu>1.0</mu><mu2>1.0</mu2></ode></friction></surface>
      </collision>
    </link>
    <joint name="right_wheel_joint" type="revolute">
      <parent>chassis</parent><child>right_wheel</child>
      <axis><xyz>0 0 1</xyz><limit><lower>-1e16</lower><upper>1e16</upper></limit></axis>
    </joint>

    <!-- ══ Front Caster ══ -->
    <link name="front_caster">
      <pose>0.540000 0 0.020000 0 0 0</pose>
      <inertial>
        <mass>0.5</mass>
        <inertia><ixx>0.000281</ixx><ixy>0</ixy><ixz>0</ixz><iyy>0.000281</iyy><iyz>0</iyz><izz>0.000281</izz></inertia>
      </inertial>
      <visual name="front_caster_visual">
        <geometry><sphere><radius>0.020000</radius></sphere></geometry>
        <material><ambient>0.3 0.3 0.3 1.0</ambient><diffuse>0.3 0.3 0.3 1.0</diffuse></material>
      </visual>
      <collision name="front_caster_collision">
        <geometry><sphere><radius>0.020000</radius></sphere></geometry>
        <surface><friction><ode><mu>0.01</mu><mu2>0.01</mu2></ode></friction></surface>
      </collision>
    </link>
    <joint name="front_caster_joint" type="ball"><parent>chassis</parent><child>front_caster</child></joint>

    <!-- ══ Rear Caster ══ -->
    <link name="rear_caster">
      <pose>-0.540000 0 0.020000 0 0 0</pose>
      <inertial>
        <mass>0.5</mass>
        <inertia><ixx>0.000281</ixx><ixy>0</ixy><ixz>0</ixz><iyy>0.000281</iyy><iyz>0</iyz><izz>0.000281</izz></inertia>
      </inertial>
      <visual name="rear_caster_visual">
        <geometry><sphere><radius>0.020000</radius></sphere></geometry>
        <material><ambient>0.3 0.3 0.3 1.0</ambient><diffuse>0.3 0.3 0.3 1.0</diffuse></material>
      </visual>
      <collision name="rear_caster_collision">
        <geometry><sphere><radius>0.020000</radius></sphere></geometry>
        <surface><friction><ode><mu>0.01</mu><mu2>0.01</mu2></ode></friction></surface>
      </collision>
    </link>
    <joint name="rear_caster_joint" type="ball"><parent>chassis</parent><child>rear_caster</child></joint>

    <!-- ══ DiffDrive Plugin ══ -->
    <plugin filename="gz-sim-diff-drive-system" name="gz::sim::systems::DiffDrive">
      <left_joint>left_wheel_joint</left_joint>
      <right_joint>right_wheel_joint</right_joint>
      <wheel_separation>0.7</wheel_separation>
      <wheel_radius>0.04</wheel_radius>
      <max_linear_acceleration>0.5</max_linear_acceleration>
      <max_angular_velocity>0.0</max_angular_velocity>
      <topic>cmd_vel</topic>
      <odom_topic>odom</odom_topic>
      <tf_topic>tf</tf_topic>
      <frame_id>odom</frame_id>
      <child_frame_id>chassis</child_frame_id>
      <odom_publish_frequency>15</odom_publish_frequency>
    </plugin>

    <plugin filename="gz-sim-joint-state-publisher-system" name="gz::sim::systems::JointStatePublisher"/>
  </model>
</sdf>
